Workbook

Sheet PARTE A 
B2: Variables Rango años, localidad y costo en dólares | H2: Población | I2: % | K2: Población | L2: Cálculo | M2: Al menos
B3: Región | C3: Grupo de Edad
C4: 15-24 | D4: 25-44 | E4: 45-64 | F4: 65 o más | H4: Grupo de edad | K4: Grupo de edad
B5: Área Metropolitana San José (AMSJ) | C5: 4.75 | D5: 5.75 | E5: 6.25 | F5: 5 | H5: 15-24 | I5: 0.2 | K5: 15-24 | L5: 2000*25% | M5: =2000*I5 -> 400
B6: Gran Área Metropolitana (GAM) | C6: 5.25 | D6: 6.5 | E6: 6.5 | F6: 6.25 | H6: 25-44 | I6: 0.3 | K6: 25-44 | L6: 2000*35% | M6: =2000*I6 -> 600
B7: Resto del país | C7: 6.5 | D7: 7.5 | E7: 7.5 | F7: 7.25 | H7: 45-64 | I7: 0.15 | K7: 45-64 | L7: 2000*20% | M7: =2000*I7 -> 300
H8: 65 o más | I8: 0.15 | K8: 65 o más | L8: 2000*20% | M8: =2000*I8 -> 300
H9: Región | K9: Región
H10: =+B5 -> Área Metropolitana San José (AMSJ) | I10: 0.4 | K10: =+H10 -> Área Metropolitana San José (AMSJ) | L10: 2000*20% | M10: =2000*I10 -> 800
H11: =+B6 -> Gran Área Metropolitana (GAM) | I11: 0.2 | K11: =+H11 -> Gran Área Metropolitana (GAM) | L11: 2000*50% | M11: =2000*I11 -> 400
H12: =+B7 -> Resto del país | I12: 0.15 | K12: =+H12 -> Resto del país | L12: 2000*30% | M12: =2000*I12 -> 300
O21: Números de personas pertenecientes a la región | P21: Número de personas pertenecientes al grupo de Edad | T21: Cantidad mínima de personas agrupadas por edad | V21: Cantidad mínima de personas a entrevistar
P22: 15-24 | Q22: 25-44 | R22: 45-64 | S22: 65 o más
O23: =+K10 -> Área Metropolitana San José (AMSJ) | P23: 0 | Q23: 0 | R23: 0 | S23: 0 | T23: 0 | U23: >= | V23: =+M10 -> 800
O24: =+K11 -> Gran Área Metropolitana (GAM) | P24: 0 | Q24: 0 | R24: 0 | S24: 0 | T24: 0 | U24: >= | V24: =+M11 -> 400
O25: =+K12 -> Resto del país | P25: 0 | Q25: 0 | R25: 0 | S25: 0 | T25: 0 | U25: >= | V25: =+M12 -> 300
O26: Número total de personas agrupadas por edad | P26: 0 | Q26: 0 | R26: 0 | S26: 0 | T26: 0
P27: >= | Q27: >= | R27: >= | S27: >=
O28: Cantidad mínima de personas a entrevistar | P28: =+M5 -> 400 | Q28: =M6 -> 600 | R28: =M7 -> 300 | S28: =M8 -> 300
O29: Costos de grupo por Edad (dólares) | P29: 0 | Q29: 0 | R29: 0 | S29: 0 | T29: 0
P32: Restricciones | Q32: LHS | X32: X11 | Y32: X12 | Z32: X13 | AA32: X14 | AB32: X21 | AC32: X22 | AD32: X23 | AE32: X24 | AF32: X31 | AG32: X32 | AH32: X33 | AI32: X34 | AJ32: Z
P33: ∑X1j | Q33: 4 | R33: >= | S33: =+V23 -> 800 | W33: Solución Óptima | X33: 1 | Y33: 1 | Z33: 1 | AA33: 1 | AB33: 1 | AC33: 1 | AD33: 1 | AE33: 1 | AF33: 1 | AG33: 1 | AH33: 1 | AI33: 1 | AJ33: =SUMPRODUCT(X33:AI33,X34:AI34) -> 75
P34: ∑X2j | Q34: 4 | R34: >= | S34: =+V24 -> 400 | W34: Coeficientes | X34: 4.75 | Y34: 5.75 | Z34: 6.25 | AA34: 5 | AB34: 5.25 | AC34: 6.5 | AD34: 6.5 | AE34: 6.25 | AF34: 6.5 | AG34: 7.5 | AH34: 7.5 | AI34: 7.25
P35: ∑X3j | Q35: 4 | R35: >= | S35: =+V25 -> 300 | W35: Restricciones | AJ35: LHS | AL35: RHS
P36: ∑Xi1 | Q36: 3 | R36: >= | S36: =+P28 -> 400 | W36: ∑X1j | X36: 1 | Y36: 1 | Z36: 1 | AA36: 1 | AB36: 0 | AC36: 0 | AD36: 0 | AE36: 0 | AF36: 0 | AG36: 0 | AH36: 0 | AI36: 0 | AJ36: =SUMPRODUCT(X36:AI36,X33:AI33) -> 4 | AK36: >= | AL36: =+S33 -> 800
P37: ∑Xi2 | Q37: 3 | R37: >= | S37: =+Q28 -> 600 | W37: ∑X2j | X37: 0 | Y37: 0 | Z37: 0 | AA37: 0 | AB37: 1 | AC37: 1 | AD37: 1 | AE37: 1 | AF37: 0 | AG37: 0 | AH37: 0 | AI37: 0 | AJ37: =SUMPRODUCT(X37:AI37,X33:AI33) -> 4 | AK37: >= | AL37: =+S34 -> 400
P38: ∑Xi3 | Q38: 3 | R38: >= | S38: =+R28 -> 300 | W38: ∑X3j | X38: 0 | Y38: 0 | Z38: 0 | AA38: 0 | AB38: 0 | AC38: 0 | AD38: 0 | AE38: 0 | AF38: 1 | AG38: 1 | AH38: 1 | AI38: 1 | AJ38: =SUMPRODUCT(X38:AI38,X33:AI33) -> 4 | AK38: >= | AL38: =+S35 -> 300
P39: ∑Xi4 | Q39: 3 | R39: >= | S39: =+S28 -> 300 | W39: ∑Xi1 | X39: 1 | Y39: 0 | Z39: 0 | AA39: 0 | AB39: 1 | AC39: 0 | AD39: 0 | AE39: 0 | AF39: 1 | AG39: 0 | AH39: 0 | AI39: 0 | AJ39: =SUMPRODUCT(X39:AI39,X33:AI33) -> 3 | AK39: >= | AL39: =+S36 -> 400
P40: ∑∑Xij | Q40: 12 | R40: = | S40: 2000 | W40: ∑Xi2 | X40: 0 | Y40: 1 | Z40: 0 | AA40: 0 | AB40: 0 | AC40: 1 | AD40: 0 | AE40: 0 | AF40: 0 | AG40: 1 | AH40: 0 | AI40: 0 | AJ40: =SUMPRODUCT(X40:AI40,X33:AI33) -> 3 | AK40: >= | AL40: =+S37 -> 600
W41: ∑Xi3 | X41: 0 | Y41: 0 | Z41: 1 | AA41: 0 | AB41: 0 | AC41: 0 | AD41: 1 | AE41: 0 | AF41: 0 | AG41: 0 | AH41: 1 | AI41: 0 | AJ41: =SUMPRODUCT(X41:AI41,X33:AI33) -> 3 | AK41: >= | AL41: =+S38 -> 300
W42: ∑Xi4 | X42: 0 | Y42: 0 | Z42: 0 | AA42: 1 | AB42: 0 | AC42: 0 | AD42: 0 | AE42: 1 | AF42: 0 | AG42: 0 | AH42: 0 | AI42: 1 | AJ42: =SUMPRODUCT(X42:AI42,X33:AI33) -> 3 | AK42: >= | AL42: =+S39 -> 300
W43: ∑∑Xij | X43: 1 | Y43: 1 | Z43: 1 | AA43: 1 | AB43: 1 | AC43: 1 | AD43: 1 | AE43: 1 | AF43: 1 | AG43: 1 | AH43: 1 | AI43: 1 | AJ43: =SUMPRODUCT(X43:AI43,X33:AI33) -> 12 | AK43: = | AL43: =+S40 -> 2000
X46: SIN SOLVER
X47: X11 | Y47: X12 | Z47: X13 | AA47: X14 | AB47: X21 | AC47: X22 | AD47: X23 | AE47: X24 | AF47: X31 | AG47: X32 | AH47: X33 | AI47: X34 | AJ47: Z
W48: Solución Óptima | X48: 1 | Y48: 1 | Z48: 1 | AA48: 1 | AB48: 1 | AC48: 1 | AD48: 1 | AE48: 1 | AF48: 1 | AG48: 1 | AH48: 1 | AI48: 1 | AJ48: =SUMPRODUCT(X49:AI49,X48:AI48) -> 75
W49: Coeficientes | X49: 4.75 | Y49: 6.5 | Z49: 6.5 | AA49: 5 | AB49: 5.25 | AC49: 5.75 | AD49: 6.25 | AE49: 6.25 | AF49: 6.5 | AG49: 7.5 | AH49: 7.5 | AI49: 7.25
W50: Restricciones | AJ50: LHS | AL50: RHS
W51: ∑X1j | X51: 1 | Y51: 1 | Z51: 1 | AA51: 1 | AB51: 0 | AC51: 0 | AD51: 0 | AE51: 0 | AF51: 0 | AG51: 0 | AH51: 0 | AI51: 0 | AJ51: =SUMPRODUCT(X51:AI51,X48:AI48) -> 4 | AK51: ≥ | AL51: =+AL36 -> 800
W52: ∑X2j | X52: 0 | Y52: 0 | Z52: 0 | AA52: 0 | AB52: 1 | AC52: 1 | AD52: 1 | AE52: 1 | AF52: 0 | AG52: 0 | AH52: 0 | AI52: 0 | AJ52: =SUMPRODUCT(X52:AI52,X48:AI48) -> 4 | AK52: ≥ | AL52: =+AL37 -> 400
W53: ∑X3j | X53: 0 | Y53: 0 | Z53: 0 | AA53: 0 | AB53: 0 | AC53: 0 | AD53: 0 | AE53: 0 | AF53: 1 | AG53: 1 | AH53: 1 | AI53: 1 | AJ53: =SUMPRODUCT(X53:AI53,X48:AI48) -> 4 | AK53: ≥ | AL53: =+AL38 -> 300
...

Sheet SOLVER a) y b
C1: CON SOLVER | W1: 4.75 | X1: 5.75 | Y1: 6.25 | Z1: 5
C2: X11 | D2: X12 | E2: X13 | F2: X14 | G2: X21 | H2: X22 | I2: X23 | J2: X24 | K2: X31 | L2: X32 | M2: X33 | N2: X34 | O2: Z
B3: Solución Óptima | C3: 400 | D3: 600 | E3: 0 | F3: 300 | G3: 400 | H3: 0 | I3: 0 | J3: 0 | K3: 0 | L3: 0 | M3: 300 | N3: 0 | O3: =SUMPRODUCT(C4:N4,C3:N3) -> 11200
B4: Coeficientes | C4: 4.75 | D4: 5.75 | E4: 6.25 | F4: 5 | G4: 5.25 | H4: 6.5 | I4: 6.5 | J4: 6.25 | K4: 6.5 | L4: 7.5 | M4: 7.5 | N4: 7.25
B5: Restricciones | O5: LHS | Q5: RHS
B6: ∑X1j | C6: 1 | D6: 1 | E6: 1 | F6: 1 | G6: 0 | H6: 0 | I6: 0 | J6: 0 | K6: 0 | L6: 0 | M6: 0 | N6: 0 | O6: =SUMPRODUCT(C6:N6,C3:N3) -> 1300 | P6: ≥ | Q6: =+Q23 -> 800
B7: ∑X2j | C7: 0 | D7: 0 | E7: 0 | F7: 0 | G7: 1 | H7: 1 | I7: 1 | J7: 1 | K7: 0 | L7: 0 | M7: 0 | N7: 0 | O7: =SUMPRODUCT(C7:N7,C3:N3) -> 400 | P7: ≥ | Q7: =+Q24 -> 400
B8: ∑X3j | C8: 0 | D8: 0 | E8: 0 | F8: 0 | G8: 0 | H8: 0 | I8: 0 | J8: 0 | K8: 1 | L8: 1 | M8: 1 | N8: 1 | O8: =SUMPRODUCT(C8:N8,C3:N3) -> 300 | P8: ≥ | Q8: =+Q25 -> 300
B9: ∑Xi1 | C9: 1 | D9: 0 | E9: 0 | F9: 0 | G9: 1 | H9: 0 | I9: 0 | J9: 0 | K9: 1 | L9: 0 | M9: 0 | N9: 0 | O9: =SUMPRODUCT(C9:N9,C3:N3) -> 800 | P9: ≥ | Q9: =+Q26 -> 400
B10: ∑Xi2 | C10: 0 | D10: 1 | E10: 0 | F10: 0 | G10: 0 | H10: 1 | I10: 0 | J10: 0 | K10: 0 | L10: 1 | M10: 0 | N10: 0 | O10: =SUMPRODUCT(C10:N10,C3:N3) -> 600 | P10: ≥ | Q10: =+Q27 -> 600
B11: ∑Xi3 | C11: 0 | D11: 0 | E11: 1 | F11: 0 | G11: 0 | H11: 0 | I11: 1 | J11: 0 | K11: 0 | L11: 0 | M11: 1 | N11: 0 | O11: =SUMPRODUCT(C11:N11,C3:N3) -> 300 | P11: ≥ | Q11: =+Q28 -> 300
B12: ∑Xi4 | C12: 0 | D12: 0 | E12: 0 | F12: 1 | G12: 0 | H12: 0 | I12: 0 | J12: 1 | K12: 0 | L12: 0 | M12: 0 | N12: 1 | O12: =SUMPRODUCT(C12:N12,C3:N3) -> 300 | P12: ≥ | Q12: =+Q29 -> 300
B13: ∑∑Xij | C13: 1 | D13: 1 | E13: 1 | F13: 1 | G13: 1 | H13: 1 | I13: 1 | J13: 1 | K13: 1 | L13: 1 | M13: 1 | N13: 1 | O13: =SUMPRODUCT(C13:N13,C3:N3) -> 2000 | P13: = | Q13: 2000
L15: B) | M15: COTIZACIÓN 15% | R15: =+$O$3*1.15 -> 12880
C18: SIN APLICAR SOLVER
C19: X11 | D19: X12 | E19: X13 | F19: X14 | G19: X21 | H19: X22 | I19: X23 | J19: X24 | K19: X31 | L19: X32 | M19: X33 | N19: X34 | O19: Z
B20: Solución Óptima | C20: 1 | D20: 1 | E20: 1 | F20: 1 | G20: 1 | H20: 1 | I20: 1 | J20: 1 | K20: 1 | L20: 1 | M20: 1 | N20: 1 | O20: =SUMPRODUCT(C21:N21,C20:N20) -> 75
B21: Coeficientes | C21: 4.75 | D21: 5.75 | E21: 6.25 | F21: 5 | G21: 5.25 | H21: 6.5 | I21: 6.5 | J21: 6.25 | K21: 6.5 | L21: 7.5 | M21: 7.5 | N21: 7.25
B22: Restricciones | O22: LHS | Q22: RHS
B23: ∑X1j | C23: 1 | D23: 1 | E23: 1 | F23: 1 | G23: 0 | H23: 0 | I23: 0 | J23: 0 | K23: 0 | L23: 0 | M23: 0 | N23: 0 | O23: =SUMPRODUCT(C23:N23,C20:N20) -> 4 | P23: ≥ | Q23: =+'PARTE A '!AL36 -> 800
B24: ∑X2j | C24: 0 | D24: 0 | E24: 0 | F24: 0 | G24: 1 | H24: 1 | I24: 1 | J24: 1 | K24: 0 | L24: 0 | M24: 0 | N24: 0 | O24: =SUMPRODUCT(C24:N24,C20:N20) -> 4 | P24: ≥ | Q24: =+'PARTE A '!AL37 -> 400
B25: ∑X3j | C25: 0 | D25: 0 | E25: 0 | F25: 0 | G25: 0 | H25: 0 | I25: 0 | J25: 0 | K25: 1 | L25: 1 | M25: 1 | N25: 1 | O25: =SUMPRODUCT(C25:N25,C20:N20) -> 4 | P25: ≥ | Q25: =+'PARTE A '!AL38 -> 300
B26: ∑Xi1 | C26: 1 | D26: 0 | E26: 0 | F26: 0 | G26: 1 | H26: 0 | I26: 0 | J26: 0 | K26: 1 | L26: 0 | M26: 0 | N26: 0 | O26: =SUMPRODUCT(C26:N26,C20:N20) -> 3 | P26: ≥ | Q26: =+'PARTE A '!AL39 -> 400
B27: ∑Xi2 | C27: 0 | D27: 1 | E27: 0 | F27: 0 | G27: 0 | H27: 1 | I27: 0 | J27: 0 | K27: 0 | L27: 1 | M27: 0 | N27: 0 | O27: =SUMPRODUCT(C27:N27,C20:N20) -> 3 | P27: ≥ | Q27: =+'PARTE A '!AL40 -> 600
B28: ∑Xi3 | C28: 0 | D28: 0 | E28: 1 | F28: 0 | G28: 0 | H28: 0 | I28: 1 | J28: 0 | K28: 0 | L28: 0 | M28: 1 | N28: 0 | O28: =SUMPRODUCT(C28:N28,C20:N20) -> 3 | P28: ≥ | Q28: =+'PARTE A '!AL41 -> 300
B29: ∑Xi4 | C29: 0 | D29: 0 | E29: 0 | F29: 1 | G29: 0 | H29: 0 | I29: 0 | J29: 1 | K29: 0 | L29: 0 | M29: 0 | N29: 1 | O29: =SUMPRODUCT(C29:N29,C20:N20) -> 3 | P29: ≥ | Q29: =+'PARTE A '!AL42 -> 300
B30: ∑∑Xij | C30: 1 | D30: 1 | E30: 1 | F30: 1 | G30: 1 | H30: 1 | I30: 1 | J30: 1 | K30: 1 | L30: 1 | M30: 1 | N30: 1 | O30: =SUMPRODUCT(C30:N30,C20:N20) -> 12 | P30: = | Q30: 2000

Sheet SOLVER C
C1: CON SOLVER
C2: X11 | D2: X12 | E2: X13 | F2: X14 | G2: X21 | H2: X22 | I2: X23 | J2: X24 | K2: X31 | L2: X32 | M2: X33 | N2: X34 | O2: Z
B3: Solución Óptima | C3: 550 | D3: 500 | E3: 50 | F3: 200 | G3: 200 | H3: 50 | I3: 100 | J3: 50 | K3: 50 | L3: 50 | M3: 150 | N3: 50 | O3: =SUMPRODUCT(C4:N4,C3:N3) -> 11325
B4: Coeficientes | C4: 4.75 | D4: 5.75 | E4: 6.25 | F4: 5 | G4: 5.25 | H4: 6.5 | I4: 6.5 | J4: 6.25 | K4: 6.5 | L4: 7.5 | M4: 7.5 | N4: 7.25
B5: Restricciones | O5: LHS | Q5: RHS
B6: ∑X1j | C6: 1 | D6: 1 | E6: 1 | F6: 1 | G6: 0 | H6: 0 | I6: 0 | J6: 0 | K6: 0 | L6: 0 | M6: 0 | N6: 0 | O6: =SUMPRODUCT(C6:N6,C3:N3) -> 1300 | P6: ≥ | Q6: 800
B7: ∑X2j | C7: 0 | D7: 0 | E7: 0 | F7: 0 | G7: 1 | H7: 1 | I7: 1 | J7: 1 | K7: 0 | L7: 0 | M7: 0 | N7: 0 | O7: =SUMPRODUCT(C7:N7,C3:N3) -> 400 | P7: ≥ | Q7: 400
B8: ∑X3j | C8: 0 | D8: 0 | E8: 0 | F8: 0 | G8: 0 | H8: 0 | I8: 0 | J8: 0 | K8: 1 | L8: 1 | M8: 1 | N8: 1 | O8: =SUMPRODUCT(C8:N8,C3:N3) -> 300 | P8: ≥ | Q8: 300
B9: ∑Xi1 | C9: 1 | D9: 0 | E9: 0 | F9: 0 | G9: 1 | H9: 0 | I9: 0 | J9: 0 | K9: 1 | L9: 0 | M9: 0 | N9: 0 | O9: =SUMPRODUCT(C9:N9,C3:N3) -> 800 | P9: ≥ | Q9: 400
B10: ∑Xi2 | C10: 0 | D10: 1 | E10: 0 | F10: 0 | G10: 0 | H10: 1 | I10: 0 | J10: 0 | K10: 0 | L10: 1 | M10: 0 | N10: 0 | O10: =SUMPRODUCT(C10:N10,C3:N3) -> 600 | P10: ≥ | Q10: 600
B11: ∑Xi3 | C11: 0 | D11: 0 | E11: 1 | F11: 0 | G11: 0 | H11: 0 | I11: 1 | J11: 0 | K11: 0 | L11: 0 | M11: 1 | N11: 0 | O11: =SUMPRODUCT(C11:N11,C3:N3) -> 300 | P11: ≥ | Q11: 300
B12: ∑Xi4 | C12: 0 | D12: 0 | E12: 0 | F12: 1 | G12: 0 | H12: 0 | I12: 0 | J12: 1 | K12: 0 | L12: 0 | M12: 0 | N12: 1 | O12: =SUMPRODUCT(C12:N12,C3:N3) -> 300 | P12: ≥ | Q12: 300
B13: ∑∑Xij | C13: 1 | D13: 1 | E13: 1 | F13: 1 | G13: 1 | H13: 1 | I13: 1 | J13: 1 | K13: 1 | L13: 1 | M13: 1 | N13: 1 | O13: =SUMPRODUCT(C13:N13,C3:N3) -> 2000 | P13: = | Q13: 2000
M15: COTIZACIÓN 15% | R15: =+$O$3*1.15 -> 13023.75

Sheet SOLVER d
C1: CON SOLVER
C2: X11 | D2: X12 | E2: X13 | F2: X14 | G2: X21 | H2: X22 | I2: X23 | J2: X24 | K2: X31 | L2: X32 | M2: X33 | N2: X34 | O2: Z
B3: Solución Óptima | C3: 50 | D3: 150 | E3: 50 | F3: 400 | G3: 500 | H3: 300 | I3: 200 | J3: 50 | K3: 50 | L3: 150 | M3: 50 | N3: 50 | O3: =SUMPRODUCT(C4:N4,C3:N3) -> 11787.5
B4: Coeficientes | C4: 4.75 | D4: 5.75 | E4: 6.25 | F4: 5 | G4: 5.25 | H4: 6.5 | I4: 6.5 | J4: 6.25 | K4: 6.5 | L4: 7.5 | M4: 7.5 | N4: 7.25
B5: Restricciones | O5: LHS | Q5: RHS
B6: ∑X1j | C6: 1 | D6: 1 | E6: 1 | F6: 1 | G6: 0 | H6: 0 | I6: 0 | J6: 0 | K6: 0 | L6: 0 | M6: 0 | N6: 0 | O6: =SUMPRODUCT(C6:N6,C3:N3) -> 650 | P6: ≥ | Q6: 800
B7: ∑X2j | C7: 0 | D7: 0 | E7: 0 | F7: 0 | G7: 1 | H7: 1 | I7: 1 | J7: 1 | K7: 0 | L7: 0 | M7: 0 | N7: 0 | O7: =SUMPRODUCT(C7:N7,C3:N3) -> 1050 | P7: ≥ | Q7: 400
B8: ∑X3j | C8: 0 | D8: 0 | E8: 0 | F8: 0 | G8: 0 | H8: 0 | I8: 0 | J8: 0 | K8: 1 | L8: 1 | M8: 1 | N8: 1 | O8: =SUMPRODUCT(C8:N8,C3:N3) -> 300 | P8: ≥ | Q8: 300
B9: ∑Xi1 | C9: 1 | D9: 0 | E9: 0 | F9: 0 | G9: 1 | H9: 0 | I9: 0 | J9: 0 | K9: 1 | L9: 0 | M9: 0 | N9: 0 | O9: =SUMPRODUCT(C9:N9,C3:N3) -> 600 | P9: ≥ | Q9: 400
B10: ∑Xi2 | C10: 0 | D10: 1 | E10: 0 | F10: 0 | G10: 0 | H10: 1 | I10: 0 | J10: 0 | K10: 0 | L10: 1 | M10: 0 | N10: 0 | O10: =SUMPRODUCT(C10:N10,C3:N3) -> 600 | P10: ≥ | Q10: 600
B11: ∑Xi3 | C11: 0 | D11: 0 | E11: 1 | F11: 0 | G11: 0 | H11: 0 | I11: 1 | J11: 0 | K11: 0 | L11: 0 | M11: 1 | N11: 0 | O11: =SUMPRODUCT(C11:N11,C3:N3) -> 300 | P11: ≥ | Q11: 300
B12: ∑Xi4 | C12: 0 | D12: 0 | E12: 0 | F12: 1 | G12: 0 | H12: 0 | I12: 0 | J12: 1 | K12: 0 | L12: 0 | M12: 0 | N12: 1 | O12: =SUMPRODUCT(C12:N12,C3:N3) -> 500 | P12: ≥ | Q12: 300
B13: ∑∑Xij | C13: 1 | D13: 1 | E13: 1 | F13: 1 | G13: 1 | H13: 1 | I13: 1 | J13: 1 | K13: 1 | L13: 1 | M13: 1 | N13: 1 | O13: =SUMPRODUCT(C13:N13,$C$3:$N$3) -> 2000 | P13: = | Q13: 2000
B14: Grupo 15–24 ≤ 600 | C14: 1 | D14: 0 | E14: 0 | F14: 0 | G14: 1 | H14: 0 | I14: 0 | J14: 0 | K14: 1 | L14: 0 | M14: 0 | N14: 0 | O14: =SUMPRODUCT(C14:N14,$C$3:$N$3) -> 600 | P14: ≤ | Q14: 600
B15: AMSJ ≤ 650 | C15: 1 | D15: 1 | E15: 1 | F15: 1 | G15: 0 | H15: 0 | I15: 0 | J15: 0 | K15: 0 | L15: 0 | M15: 0 | N15: 0 | O15: =SUMPRODUCT(C15:N15,$C$3:$N$3) -> 650 | P15: ≤ | Q15: 650
L17: COTIZACIÓN 15% | Q17: =+$O$3*1.15 -> 13555.625
W20: Restricciones | X20: LHS
W21: ∑X1j | X21: 4 | Y21: >= | Z21: =+Q6 -> 800
W22: ∑X2j | X22: 4 | Y22: >= | Z22: =+Q7 -> 400
W23: ∑X3j | X23: 4 | Y23: >= | Z23: =+Q8 -> 300
W24: ∑Xi1 | X24: 3 | Y24: >= | Z24: =+Q9 -> 400
W25: ∑Xi2 | X25: 3 | Y25: >= | Z25: =+Q10 -> 600
W26: ∑Xi3 | X26: 3 | Y26: >= | Z26: =+Q11 -> 300
W27: ∑Xi4 | X27: 3 | Y27: >= | Z27: =+Q12 -> 300
W28: ∑∑Xij | X28: 12 | Y28: = | Z28: =+Q13 -> 2000

Sheet SOLVER E)
C1: CON SOLVER
C2: X11 | D2: X12 | E2: X13 | F2: X14 | G2: X21 | H2: X22 | I2: X23 | J2: X24 | K2: X31 | L2: X32 | M2: X33 | N2: X34 | O2: Z
B3: Solución Óptima | C3: 50 | D3: 50 | E3: 50 | F3: 500 | G3: 200 | H3: 500 | I3: 200 | J3: 150 | K3: 150 | L3: 50 | M3: 50 | N3: 50 | O3: =SUMPRODUCT(C4:N4,C3:N3) -> 12425
B4: Coeficientes | C4: 6.5 | D4: 5.75 | E4: 6.25 | F4: 5 | G4: 6.75 | H4: 6.5 | I4: 6.5 | J4: 6.25 | K4: 7 | L4: 7.5 | M4: 7.5 | N4: 7.25
B5: Restricciones | O5: LHS | Q5: RHS
B6: ∑X1j | C6: 1 | D6: 1 | E6: 1 | F6: 1 | G6: 0 | H6: 0 | I6: 0 | J6: 0 | K6: 0 | L6: 0 | M6: 0 | N6: 0 | O6: =SUMPRODUCT(C6:N6,C3:N3) -> 650 | P6: ≥ | Q6: 600
B7: ∑X2j | C7: 0 | D7: 0 | E7: 0 | F7: 0 | G7: 1 | H7: 1 | I7: 1 | J7: 1 | K7: 0 | L7: 0 | M7: 0 | N7: 0 | O7: =SUMPRODUCT(C7:N7,C3:N3) -> 1050 | P7: ≥ | Q7: 400 | W7: Variables Rango años, localidad y costo en dólares
B8: ∑X3j | C8: 0 | D8: 0 | E8: 0 | F8: 0 | G8: 0 | H8: 0 | I8: 0 | J8: 0 | K8: 1 | L8: 1 | M8: 1 | N8: 1 | O8: =SUMPRODUCT(C8:N8,C3:N3) -> 300 | P8: ≥ | Q8: 300 | W8: Región | X8: Grupo de Edad
B9: ∑Xi1 | C9: 1 | D9: 0 | E9: 0 | F9: 0 | G9: 1 | H9: 0 | I9: 0 | J9: 0 | K9: 1 | L9: 0 | M9: 0 | N9: 0 | O9: =SUMPRODUCT(C9:N9,C3:N3) -> 400 | P9: ≥ | Q9: 400 | X9: 15-24 | Y9: 25-44 | Z9: 45-64 | AA9: 65 o más
B10: ∑Xi2 | C10: 0 | D10: 1 | E10: 0 | F10: 0 | G10: 0 | H10: 1 | I10: 0 | J10: 0 | K10: 0 | L10: 1 | M10: 0 | N10: 0 | O10: =SUMPRODUCT(C10:N10,C3:N3) -> 600 | P10: ≥ | Q10: 600 | W10: Área Metropolitana San José (AMSJ) | X10: 6.5 | Y10: 5.75 | Z10: 6.25 | AA10: 5
B11: ∑Xi3 | C11: 0 | D11: 0 | E11: 1 | F11: 0 | G11: 0 | H11: 0 | I11: 1 | J11: 0 | K11: 0 | L11: 0 | M11: 1 | N11: 0 | O11: =SUMPRODUCT(C11:N11,C3:N3) -> 300 | P11: ≥ | Q11: 300 | W11: Gran Área Metropolitana (GAM) | X11: 6.75 | Y11: 6.5 | Z11: 6.5 | AA11: 6.25
B12: ∑Xi4 | C12: 0 | D12: 0 | E12: 0 | F12: 1 | G12: 0 | H12: 0 | I12: 0 | J12: 1 | K12: 0 | L12: 0 | M12: 0 | N12: 1 | O12: =SUMPRODUCT(C12:N12,C3:N3) -> 700 | P12: ≥ | Q12: 300 | W12: Resto del país | X12: 7 | Y12: 7.5 | Z12: 7.5 | AA12: 7.25
B13: ∑∑Xij | C13: 1 | D13: 1 | E13: 1 | F13: 1 | G13: 1 | H13: 1 | I13: 1 | J13: 1 | K13: 1 | L13: 1 | M13: 1 | N13: 1 | O13: =SUMPRODUCT(C13:N13,$C$3:$N$3) -> 2000 | P13: = | Q13: 2000
B14: Grupo 15–24 ≤ 600 | C14: 1 | D14: 0 | E14: 0 | F14: 0 | G14: 1 | H14: 0 | I14: 0 | J14: 0 | K14: 1 | L14: 0 | M14: 0 | N14: 0 | O14: =SUMPRODUCT(C14:N14,$C$3:$N$3) -> 400 | P14: ≤ | Q14: 600
B15: AMSJ ≤ 650 | C15: 1 | D15: 1 | E15: 1 | F15: 1 | G15: 0 | H15: 0 | I15: 0 | J15: 0 | K15: 0 | L15: 0 | M15: 0 | N15: 0 | O15: =SUMPRODUCT(C15:N15,$C$3:$N$3) -> 650 | P15: ≤ | Q15: 650
L17: COTIZACIÓN 15% | Q17: =+$O$3*1.15 -> 14288.75
W20: Restricciones | X20: LHS
W21: ∑X1j | X21: 4 | Y21: >= | Z21: =+Q6 -> 600
W22: ∑X2j | X22: 4 | Y22: >= | Z22: =+Q7 -> 400
W23: ∑X3j | X23: 4 | Y23: >= | Z23: =+Q8 -> 300
W24: ∑Xi1 | X24: 3 | Y24: >= | Z24: =+Q9 -> 400
W25: ∑Xi2 | X25: 3 | Y25: >= | Z25: =+Q10 -> 600
W26: ∑Xi3 | X26: 3 | Y26: >= | Z26: =+Q11 -> 300
W27: ∑Xi4 | X27: 3 | Y27: >= | Z27: =+Q12 -> 300
W28: ∑∑Xij | X28: 12 | Y28: = | Z28: =+Q13 -> 2000
V29: Grupo 15–24 ≤ 600 | X29: 3 | Y29: ≤ | Z29: =+Q14 -> 600
V30: AMSJ ≤ 650 | X30: 4 | Y30: ≤ | Z30: =+Q15 -> 650

Sheet SOLVER F)
C1: CON SOLVER
C2: X11 | D2: X12 | E2: X13 | F2: X14 | G2: X21 | H2: X22 | I2: X23 | J2: X24 | K2: X31 | L2: X32 | M2: X33 | N2: X34 | O2: Z
B3: Solución Óptima | C3: 50 | D3: 250 | E3: 50 | F3: 50 | G3: 400 | H3: 200 | I3: 100 | J3: 300 | K3: 50 | L3: 250 | M3: 250 | N3: 50 | O3: =SUMPRODUCT(C4:N4,C3:N3) -> 13312.5
B4: Coeficientes | C4: 6.5 | D4: 5.75 | E4: 6.25 | F4: 5 | G4: 6.75 | H4: 6.5 | I4: 6.5 | J4: 6.25 | K4: 7 | L4: 7.5 | M4: 7.5 | N4: 7.25
B5: Restricciones | O5: LHS | Q5: RHS
B6: ∑X1j | C6: 1 | D6: 1 | E6: 1 | F6: 1 | G6: 0 | H6: 0 | I6: 0 | J6: 0 | K6: 0 | L6: 0 | M6: 0 | N6: 0 | O6: =SUMPRODUCT(C6:N6,C3:N3) -> 400 | P6: = | Q6: 500
B7: ∑X2j | C7: 0 | D7: 0 | E7: 0 | F7: 0 | G7: 1 | H7: 1 | I7: 1 | J7: 1 | K7: 0 | L7: 0 | M7: 0 | N7: 0 | O7: =SUMPRODUCT(C7:N7,C3:N3) -> 1000 | P7: = | Q7: 1000 | W7: Variables Rango años, localidad y costo en dólares
B8: ∑X3j | C8: 0 | D8: 0 | E8: 0 | F8: 0 | G8: 0 | H8: 0 | I8: 0 | J8: 0 | K8: 1 | L8: 1 | M8: 1 | N8: 1 | O8: =SUMPRODUCT(C8:N8,C3:N3) -> 600 | P8: = | Q8: 600 | W8: Región | X8: Grupo de Edad
B9: ∑Xi1 | C9: 1 | D9: 0 | E9: 0 | F9: 0 | G9: 1 | H9: 0 | I9: 0 | J9: 0 | K9: 1 | L9: 0 | M9: 0 | N9: 0 | O9: =SUMPRODUCT(C9:N9,C3:N3) -> 500 | P9: = | Q9: 500 | X9: 15-24 | Y9: 25-44 | Z9: 45-64 | AA9: 65 o más
B10: ∑Xi2 | C10: 0 | D10: 1 | E10: 0 | F10: 0 | G10: 0 | H10: 1 | I10: 0 | J10: 0 | K10: 0 | L10: 1 | M10: 0 | N10: 0 | O10: =SUMPRODUCT(C10:N10,C3:N3) -> 700 | P10: = | Q10: 700 | W10: Área Metropolitana San José (AMSJ) | X10: 6.5 | Y10: 5.75 | Z10: 6.25 | AA10: 5
B11: ∑Xi3 | C11: 0 | D11: 0 | E11: 1 | F11: 0 | G11: 0 | H11: 0 | I11: 1 | J11: 0 | K11: 0 | L11: 0 | M11: 1 | N11: 0 | O11: =SUMPRODUCT(C11:N11,C3:N3) -> 400 | P11: = | Q11: 400 | W11: Gran Área Metropolitana (GAM) | X11: 6.75 | Y11: 6.5 | Z11: 6.5 | AA11: 6.25
B12: ∑Xi4 | C12: 0 | D12: 0 | E12: 0 | F12: 1 | G12: 0 | H12: 0 | I12: 0 | J12: 1 | K12: 0 | L12: 0 | M12: 0 | N12: 1 | O12: =SUMPRODUCT(C12:N12,C3:N3) -> 400 | P12: = | Q12: 400 | W12: Resto del país | X12: 7 | Y12: 7.5 | Z12: 7.5 | AA12: 7.25
B13: ∑∑Xij | C13: 1 | D13: 1 | E13: 1 | F13: 1 | G13: 1 | H13: 1 | I13: 1 | J13: 1 | K13: 1 | L13: 1 | M13: 1 | N13: 1 | O13: =SUMPRODUCT(C13:N13,$C$3:$N$3) -> 2000 | P13: = | Q13: 2000
B14: Grupo 15–24 ≤ 600 | C14: 1 | D14: 0 | E14: 0 | F14: 0 | G14: 1 | H14: 0 | I14: 0 | J14: 0 | K14: 1 | L14: 0 | M14: 0 | N14: 0 | O14: =SUMPRODUCT(C14:N14,$C$3:$N$3) -> 500 | P14: ≤ | Q14: 600
B15: AMSJ ≤ 650 | C15: 1 | D15: 1 | E15: 1 | F15: 1 | G15: 0 | H15: 0 | I15: 0 | J15: 0 | K15: 0 | L15: 0 | M15: 0 | N15: 0 | O15: =SUMPRODUCT(C15:N15,$C$3:$N$3) -> 400 | P15: ≤ | Q15: 650
L17: COTIZACIÓN 15% | Q17: =+$O$3*1.15 -> 15309.375
W20: Restricciones | X20: LHS
W21: ∑X1j | X21: 4 | Y21: >= | Z21: 50 | AB21: Población | AC21: NUEVOS % | AD21: Cálculo | AE21: Al menos
W22: ∑X2j | X22: 4 | Y22: >= | Z22: 50
W23: ∑X3j | X23: 4 | Y23: >= | Z23: 50 | AB23: Grupo de edad
W24: ∑Xi1 | X24: 3 | Y24: >= | Z24: 50 | AB24: 15-24 | AC24: 0.25 | AD24: 2000*25% | AE24: =2000*AC24 -> 500
W25: ∑Xi2 | X25: 3 | Y25: >= | Z25: 50 | AB25: 25-44 | AC25: 0.35 | AD25: 2000*35% | AE25: =2000*AC25 -> 700
W26: ∑Xi3 | X26: 3 | Y26: >= | Z26: 50 | AB26: 45-64 | AC26: 0.2 | AD26: 2000*20% | AE26: =2000*AC26 -> 400
W27: ∑Xi4 | X27: 3 | Y27: >= | Z27: 50 | AB27: 65 o más | AC27: 0.2 | AD27: 2000*20% | AE27: =2000*AC27 -> 400
W28: ∑∑Xij | X28: 12 | Y28: = | Z28: 2000 | AB28: Región
AB29: ='PARTE A '!H10 -> Área Metropolitana San José (AMSJ) | AC29: 0.2 | AD29: 2000*20% | AE29: =2000*AC29 -> 400
AB30: ='PARTE A '!H11 -> Gran Área Metropolitana (GAM) | AC30: 0.5 | AD30: 2000*50% | AE30: =2000*AC30 -> 1000
AB31: ='PARTE A '!H12 -> Resto del país | AC31: 0.3 | AD31: 2000*30% | AE31: =2000*AC31 -> 600

Sheet RESPUESTAS
E2: COTIZACIÓN: COSTO + 15%
E5: A | F5: =+'SOLVER a) y b'!O3 -> 11200
E6: B | F6: =+F5*1.15 -> 12880
E7: C | F7: {=+'SOLVER C'!R15:S15} -> 13023.75 | G7: 0
E8: D | F8: =+'SOLVER d'!O3*1.15 -> 13555.625
E9: E | F9: =+'SOLVER E)'!Q17 -> 14288.75 | G9: COSTO F | H9: COSTO E
D10: AUMENTO | E10: F | F10: =+G10-H10 -> 887.5 | G10: =+'SOLVER F)'!O3 -> 13312.5 | H10: =+'SOLVER E)'!O3 -> 12425

Sheet SOLVER E) (2)
C1: CON SOLVER
C2: X11 | D2: X12 | E2: X13 | F2: X14 | G2: X21 | H2: X22 | I2: X23 | J2: X24 | K2: X31 | L2: X32 | M2: X33 | N2: X34 | O2: Z
B3: Solución Óptima | C3: 50 | D3: 50 | E3: 50 | F3: 250 | G3: 50 | H3: 600 | I3: 250 | J3: 100 | K3: 400 | L3: 50 | M3: 100 | N3: 50 | O3: =SUMPRODUCT(C4:N4,C3:N3) -> 12950
B4: Coeficientes | C4: 6.5 | D4: 5.75 | E4: 6.25 | F4: 5 | G4: 6.75 | H4: 6.5 | I4: 6.5 | J4: 6.25 | K4: 7 | L4: 7.5 | M4: 7.5 | N4: 7.25
B5: Restricciones | O5: LHS | Q5: RHS
B6: ∑X1j | C6: 1 | D6: 1 | E6: 1 | F6: 1 | G6: 0 | H6: 0 | I6: 0 | J6: 0 | K6: 0 | L6: 0 | M6: 0 | N6: 0 | O6: =SUMPRODUCT(C6:N6,C3:N3) -> 400 | P6: ≥ | Q6: 400
B7: ∑X2j | C7: 0 | D7: 0 | E7: 0 | F7: 0 | G7: 1 | H7: 1 | I7: 1 | J7: 1 | K7: 0 | L7: 0 | M7: 0 | N7: 0 | O7: =SUMPRODUCT(C7:N7,C3:N3) -> 1000 | P7: ≥ | Q7: 1000 | W7: Variables Rango años, localidad y costo en dólares
B8: ∑X3j | C8: 0 | D8: 0 | E8: 0 | F8: 0 | G8: 0 | H8: 0 | I8: 0 | J8: 0 | K8: 1 | L8: 1 | M8: 1 | N8: 1 | O8: =SUMPRODUCT(C8:N8,C3:N3) -> 600 | P8: ≥ | Q8: 600 | W8: Región | X8: Grupo de Edad
B9: ∑Xi1 | C9: 1 | D9: 0 | E9: 0 | F9: 0 | G9: 1 | H9: 0 | I9: 0 | J9: 0 | K9: 1 | L9: 0 | M9: 0 | N9: 0 | O9: =SUMPRODUCT(C9:N9,C3:N3) -> 500 | P9: ≥ | Q9: 500 | X9: 15-24 | Y9: 25-44 | Z9: 45-64 | AA9: 65 o más
B10: ∑Xi2 | C10: 0 | D10: 1 | E10: 0 | F10: 0 | G10: 0 | H10: 1 | I10: 0 | J10: 0 | K10: 0 | L10: 1 | M10: 0 | N10: 0 | O10: =SUMPRODUCT(C10:N10,C3:N3) -> 700 | P10: ≥ | Q10: 700 | W10: Área Metropolitana San José (AMSJ) | X10: 6.5 | Y10: 5.75 | Z10: 6.25 | AA10: 5
B11: ∑Xi3 | C11: 0 | D11: 0 | E11: 1 | F11: 0 | G11: 0 | H11: 0 | I11: 1 | J11: 0 | K11: 0 | L11: 0 | M11: 1 | N11: 0 | O11: =SUMPRODUCT(C11:N11,C3:N3) -> 400 | P11: ≥ | Q11: 400 | W11: Gran Área Metropolitana (GAM) | X11: 6.75 | Y11: 6.5 | Z11: 6.5 | AA11: 6.25
B12: ∑Xi4 | C12: 0 | D12: 0 | E12: 0 | F12: 1 | G12: 0 | H12: 0 | I12: 0 | J12: 1 | K12: 0 | L12: 0 | M12: 0 | N12: 1 | O12: =SUMPRODUCT(C12:N12,C3:N3) -> 400 | P12: ≥ | Q12: 400 | W12: Resto del país | X12: 7 | Y12: 7.5 | Z12: 7.5 | AA12: 7.25
B13: ∑∑Xij | C13: 1 | D13: 1 | E13: 1 | F13: 1 | G13: 1 | H13: 1 | I13: 1 | J13: 1 | K13: 1 | L13: 1 | M13: 1 | N13: 1 | O13: =SUMPRODUCT(C13:N13,$C$3:$N$3) -> 2000 | P13: = | Q13: 2000
B14: Grupo 15–24 ≤ 600 | C14: 1 | D14: 0 | E14: 0 | F14: 0 | G14: 1 | H14: 0 | I14: 0 | J14: 0 | K14: 1 | L14: 0 | M14: 0 | N14: 0 | O14: =SUMPRODUCT(C14:N14,$C$3:$N$3) -> 500 | P14: ≤ | Q14: 600
B15: AMSJ ≤ 650 | C15: 1 | D15: 1 | E15: 1 | F15: 1 | G15: 0 | H15: 0 | I15: 0 | J15: 0 | K15: 0 | L15: 0 | M15: 0 | N15: 0 | O15: =SUMPRODUCT(C15:N15,$C$3:$N$3) -> 400 | P15: ≤ | Q15: 650
L17: COTIZACIÓN 15% | Q17: =+$O$3*1.15 -> 14892.5
W20: Restricciones | X20: LHS
W21: ∑X1j | X21: 4 | Y21: >= | Z21: =+Q6 -> 400
W22: ∑X2j | X22: 4 | Y22: >= | Z22: =+Q7 -> 1000
W23: ∑X3j | X23: 4 | Y23: >= | Z23: =+Q8 -> 600
W24: ∑Xi1 | X24: 3 | Y24: >= | Z24: =+Q9 -> 500
W25: ∑Xi2 | X25: 3 | Y25: >= | Z25: =+Q10 -> 700
W26: ∑Xi3 | X26: 3 | Y26: >= | Z26: =+Q11 -> 400
W27: ∑Xi4 | X27: 3 | Y27: >= | Z27: =+Q12 -> 400
W28: ∑∑Xij | X28: 12 | Y28: = | Z28: =+Q13 -> 2000
V29: Grupo 15–24 ≤ 600 | X29: 3 | Y29: ≤ | Z29: =+Q14 -> 600
V30: AMSJ ≤ 650 | X30: 4 | Y30: ≤ | Z30: =+Q15 -> 650
